{
 "cells": [
  {
   "cell_type": "code",
   "execution_count": 3,
   "id": "3f746cef",
   "metadata": {},
   "outputs": [
    {
     "name": "stderr",
     "output_type": "stream",
     "text": [
      "Task exception was never retrieved\n",
      "future: <Task finished name='Task-4' coro=<BotFrameworkAdapter.process_activity() done, defined at /Users/kevinduranty/Library/Python/3.8/lib/python/site-packages/botbuilder/core/bot_framework_adapter.py:427> exception=NameError(\"name 'ebot' is not defined\")>\n",
      "Traceback (most recent call last):\n",
      "  File \"/Users/kevinduranty/Library/Python/3.8/lib/python/site-packages/botbuilder/core/bot_framework_adapter.py\", line 451, in process_activity\n",
      "    return await self.process_activity_with_identity(activity, identity, logic)\n",
      "  File \"/Users/kevinduranty/Library/Python/3.8/lib/python/site-packages/botbuilder/core/bot_framework_adapter.py\", line 493, in process_activity_with_identity\n",
      "    await self.run_pipeline(context, logic)\n",
      "  File \"/Users/kevinduranty/Library/Python/3.8/lib/python/site-packages/botbuilder/core/bot_adapter.py\", line 135, in run_pipeline\n",
      "    raise error\n",
      "  File \"/Users/kevinduranty/Library/Python/3.8/lib/python/site-packages/botbuilder/core/bot_adapter.py\", line 128, in run_pipeline\n",
      "    return await self._middleware.receive_activity_with_status(\n",
      "  File \"/Users/kevinduranty/Library/Python/3.8/lib/python/site-packages/botbuilder/core/middleware_set.py\", line 69, in receive_activity_with_status\n",
      "    return await self.receive_activity_internal(context, callback)\n",
      "  File \"/Users/kevinduranty/Library/Python/3.8/lib/python/site-packages/botbuilder/core/middleware_set.py\", line 79, in receive_activity_internal\n",
      "    return await callback(context)\n",
      "  File \"/var/folders/pd/d9xkkvws5r5f_x34lthx34ph0000gn/T/ipykernel_3730/1317316088.py\", line 31, in turn_call\n",
      "    await ebot.on_turn(turn_context)\n",
      "NameError: name 'ebot' is not defined\n",
      "Task exception was never retrieved\n",
      "future: <Task finished name='Task-5' coro=<BotFrameworkAdapter.process_activity() done, defined at /Users/kevinduranty/Library/Python/3.8/lib/python/site-packages/botbuilder/core/bot_framework_adapter.py:427> exception=NameError(\"name 'ebot' is not defined\")>\n",
      "Traceback (most recent call last):\n",
      "  File \"/Users/kevinduranty/Library/Python/3.8/lib/python/site-packages/botbuilder/core/bot_framework_adapter.py\", line 451, in process_activity\n",
      "    return await self.process_activity_with_identity(activity, identity, logic)\n",
      "  File \"/Users/kevinduranty/Library/Python/3.8/lib/python/site-packages/botbuilder/core/bot_framework_adapter.py\", line 493, in process_activity_with_identity\n",
      "    await self.run_pipeline(context, logic)\n",
      "  File \"/Users/kevinduranty/Library/Python/3.8/lib/python/site-packages/botbuilder/core/bot_adapter.py\", line 135, in run_pipeline\n",
      "    raise error\n",
      "  File \"/Users/kevinduranty/Library/Python/3.8/lib/python/site-packages/botbuilder/core/bot_adapter.py\", line 128, in run_pipeline\n",
      "    return await self._middleware.receive_activity_with_status(\n",
      "  File \"/Users/kevinduranty/Library/Python/3.8/lib/python/site-packages/botbuilder/core/middleware_set.py\", line 69, in receive_activity_with_status\n",
      "    return await self.receive_activity_internal(context, callback)\n",
      "  File \"/Users/kevinduranty/Library/Python/3.8/lib/python/site-packages/botbuilder/core/middleware_set.py\", line 79, in receive_activity_internal\n",
      "    return await callback(context)\n",
      "  File \"/var/folders/pd/d9xkkvws5r5f_x34lthx34ph0000gn/T/ipykernel_3730/1317316088.py\", line 31, in turn_call\n",
      "    await ebot.on_turn(turn_context)\n",
      "NameError: name 'ebot' is not defined\n",
      "Task exception was never retrieved\n",
      "future: <Task finished name='Task-6' coro=<BotFrameworkAdapter.process_activity() done, defined at /Users/kevinduranty/Library/Python/3.8/lib/python/site-packages/botbuilder/core/bot_framework_adapter.py:427> exception=NameError(\"name 'ebot' is not defined\")>\n",
      "Traceback (most recent call last):\n",
      "  File \"/Users/kevinduranty/Library/Python/3.8/lib/python/site-packages/botbuilder/core/bot_framework_adapter.py\", line 451, in process_activity\n",
      "    return await self.process_activity_with_identity(activity, identity, logic)\n",
      "  File \"/Users/kevinduranty/Library/Python/3.8/lib/python/site-packages/botbuilder/core/bot_framework_adapter.py\", line 493, in process_activity_with_identity\n",
      "    await self.run_pipeline(context, logic)\n",
      "  File \"/Users/kevinduranty/Library/Python/3.8/lib/python/site-packages/botbuilder/core/bot_adapter.py\", line 135, in run_pipeline\n",
      "    raise error\n",
      "  File \"/Users/kevinduranty/Library/Python/3.8/lib/python/site-packages/botbuilder/core/bot_adapter.py\", line 128, in run_pipeline\n",
      "    return await self._middleware.receive_activity_with_status(\n",
      "  File \"/Users/kevinduranty/Library/Python/3.8/lib/python/site-packages/botbuilder/core/middleware_set.py\", line 69, in receive_activity_with_status\n",
      "    return await self.receive_activity_internal(context, callback)\n",
      "  File \"/Users/kevinduranty/Library/Python/3.8/lib/python/site-packages/botbuilder/core/middleware_set.py\", line 79, in receive_activity_internal\n",
      "    return await callback(context)\n",
      "  File \"/var/folders/pd/d9xkkvws5r5f_x34lthx34ph0000gn/T/ipykernel_3730/1317316088.py\", line 31, in turn_call\n",
      "    await ebot.on_turn(turn_context)\n",
      "NameError: name 'ebot' is not defined\n"
     ]
    },
    {
     "name": "stdout",
     "output_type": "stream",
     "text": [
      " * Serving Flask app '__main__' (lazy loading)\n",
      " * Environment: production\n",
      "\u001b[31m   WARNING: This is a development server. Do not use it in a production deployment.\u001b[0m\n",
      "\u001b[2m   Use a production WSGI server instead.\u001b[0m\n",
      " * Debug mode: off\n"
     ]
    },
    {
     "name": "stderr",
     "output_type": "stream",
     "text": [
      " * Running on http://localhost:3978 (Press CTRL+C to quit)\n",
      "[2022-05-05 17:13:02,689] ERROR in app: Exception on /api/messages [POST]\n",
      "Traceback (most recent call last):\n",
      "  File \"/Library/Frameworks/Python.framework/Versions/3.8/lib/python3.8/site-packages/flask/app.py\", line 2077, in wsgi_app\n",
      "    response = self.full_dispatch_request()\n",
      "  File \"/Library/Frameworks/Python.framework/Versions/3.8/lib/python3.8/site-packages/flask/app.py\", line 1525, in full_dispatch_request\n",
      "    rv = self.handle_user_exception(e)\n",
      "  File \"/Library/Frameworks/Python.framework/Versions/3.8/lib/python3.8/site-packages/flask/app.py\", line 1523, in full_dispatch_request\n",
      "    rv = self.dispatch_request()\n",
      "  File \"/Library/Frameworks/Python.framework/Versions/3.8/lib/python3.8/site-packages/flask/app.py\", line 1509, in dispatch_request\n",
      "    return self.ensure_sync(self.view_functions[rule.endpoint])(**req.view_args)\n",
      "  File \"/var/folders/pd/d9xkkvws5r5f_x34lthx34ph0000gn/T/ipykernel_3730/1317316088.py\", line 34, in messages\n",
      "    loop.run_until_complete(task)\n",
      "  File \"/Library/Frameworks/Python.framework/Versions/3.8/lib/python3.8/asyncio/base_events.py\", line 592, in run_until_complete\n",
      "    self._check_running()\n",
      "  File \"/Library/Frameworks/Python.framework/Versions/3.8/lib/python3.8/asyncio/base_events.py\", line 552, in _check_running\n",
      "    raise RuntimeError('This event loop is already running')\n",
      "RuntimeError: This event loop is already running\n",
      "127.0.0.1 - - [05/May/2022 17:13:02] \"\u001b[35m\u001b[1mPOST /api/messages HTTP/1.1\u001b[0m\" 500 -\n",
      "[2022-05-05 17:13:05,145] ERROR in app: Exception on /api/messages [POST]\n",
      "Traceback (most recent call last):\n",
      "  File \"/Library/Frameworks/Python.framework/Versions/3.8/lib/python3.8/site-packages/flask/app.py\", line 2077, in wsgi_app\n",
      "    response = self.full_dispatch_request()\n",
      "  File \"/Library/Frameworks/Python.framework/Versions/3.8/lib/python3.8/site-packages/flask/app.py\", line 1525, in full_dispatch_request\n",
      "    rv = self.handle_user_exception(e)\n",
      "  File \"/Library/Frameworks/Python.framework/Versions/3.8/lib/python3.8/site-packages/flask/app.py\", line 1523, in full_dispatch_request\n",
      "    rv = self.dispatch_request()\n",
      "  File \"/Library/Frameworks/Python.framework/Versions/3.8/lib/python3.8/site-packages/flask/app.py\", line 1509, in dispatch_request\n",
      "    return self.ensure_sync(self.view_functions[rule.endpoint])(**req.view_args)\n",
      "  File \"/var/folders/pd/d9xkkvws5r5f_x34lthx34ph0000gn/T/ipykernel_3730/1317316088.py\", line 34, in messages\n",
      "    loop.run_until_complete(task)\n",
      "  File \"/Library/Frameworks/Python.framework/Versions/3.8/lib/python3.8/asyncio/base_events.py\", line 592, in run_until_complete\n",
      "    self._check_running()\n",
      "  File \"/Library/Frameworks/Python.framework/Versions/3.8/lib/python3.8/asyncio/base_events.py\", line 552, in _check_running\n",
      "    raise RuntimeError('This event loop is already running')\n",
      "RuntimeError: This event loop is already running\n",
      "127.0.0.1 - - [05/May/2022 17:13:05] \"\u001b[35m\u001b[1mPOST /api/messages HTTP/1.1\u001b[0m\" 500 -\n",
      "[2022-05-05 17:13:08,234] ERROR in app: Exception on /api/messages [POST]\n",
      "Traceback (most recent call last):\n",
      "  File \"/Library/Frameworks/Python.framework/Versions/3.8/lib/python3.8/site-packages/flask/app.py\", line 2077, in wsgi_app\n",
      "    response = self.full_dispatch_request()\n",
      "  File \"/Library/Frameworks/Python.framework/Versions/3.8/lib/python3.8/site-packages/flask/app.py\", line 1525, in full_dispatch_request\n",
      "    rv = self.handle_user_exception(e)\n",
      "  File \"/Library/Frameworks/Python.framework/Versions/3.8/lib/python3.8/site-packages/flask/app.py\", line 1523, in full_dispatch_request\n",
      "    rv = self.dispatch_request()\n",
      "  File \"/Library/Frameworks/Python.framework/Versions/3.8/lib/python3.8/site-packages/flask/app.py\", line 1509, in dispatch_request\n",
      "    return self.ensure_sync(self.view_functions[rule.endpoint])(**req.view_args)\n",
      "  File \"/var/folders/pd/d9xkkvws5r5f_x34lthx34ph0000gn/T/ipykernel_3730/1317316088.py\", line 34, in messages\n",
      "    loop.run_until_complete(task)\n",
      "  File \"/Library/Frameworks/Python.framework/Versions/3.8/lib/python3.8/asyncio/base_events.py\", line 592, in run_until_complete\n",
      "    self._check_running()\n",
      "  File \"/Library/Frameworks/Python.framework/Versions/3.8/lib/python3.8/asyncio/base_events.py\", line 552, in _check_running\n",
      "    raise RuntimeError('This event loop is already running')\n",
      "RuntimeError: This event loop is already running\n",
      "127.0.0.1 - - [05/May/2022 17:13:08] \"\u001b[35m\u001b[1mPOST /api/messages HTTP/1.1\u001b[0m\" 500 -\n",
      "[2022-05-05 17:13:18,327] ERROR in app: Exception on /api/messages [POST]\n",
      "Traceback (most recent call last):\n",
      "  File \"/Library/Frameworks/Python.framework/Versions/3.8/lib/python3.8/site-packages/flask/app.py\", line 2077, in wsgi_app\n",
      "    response = self.full_dispatch_request()\n",
      "  File \"/Library/Frameworks/Python.framework/Versions/3.8/lib/python3.8/site-packages/flask/app.py\", line 1525, in full_dispatch_request\n",
      "    rv = self.handle_user_exception(e)\n",
      "  File \"/Library/Frameworks/Python.framework/Versions/3.8/lib/python3.8/site-packages/flask/app.py\", line 1523, in full_dispatch_request\n",
      "    rv = self.dispatch_request()\n",
      "  File \"/Library/Frameworks/Python.framework/Versions/3.8/lib/python3.8/site-packages/flask/app.py\", line 1509, in dispatch_request\n",
      "    return self.ensure_sync(self.view_functions[rule.endpoint])(**req.view_args)\n",
      "  File \"/var/folders/pd/d9xkkvws5r5f_x34lthx34ph0000gn/T/ipykernel_3730/1317316088.py\", line 34, in messages\n",
      "    loop.run_until_complete(task)\n",
      "  File \"/Library/Frameworks/Python.framework/Versions/3.8/lib/python3.8/asyncio/base_events.py\", line 592, in run_until_complete\n",
      "    self._check_running()\n",
      "  File \"/Library/Frameworks/Python.framework/Versions/3.8/lib/python3.8/asyncio/base_events.py\", line 552, in _check_running\n",
      "    raise RuntimeError('This event loop is already running')\n",
      "RuntimeError: This event loop is already running\n",
      "127.0.0.1 - - [05/May/2022 17:13:18] \"\u001b[35m\u001b[1mPOST /api/messages HTTP/1.1\u001b[0m\" 500 -\n",
      "Task exception was never retrieved\n",
      "future: <Task finished name='Task-7' coro=<BotFrameworkAdapter.process_activity() done, defined at /Users/kevinduranty/Library/Python/3.8/lib/python/site-packages/botbuilder/core/bot_framework_adapter.py:427> exception=NameError(\"name 'ebot' is not defined\")>\n",
      "Traceback (most recent call last):\n",
      "  File \"/Users/kevinduranty/Library/Python/3.8/lib/python/site-packages/botbuilder/core/bot_framework_adapter.py\", line 451, in process_activity\n",
      "    return await self.process_activity_with_identity(activity, identity, logic)\n",
      "  File \"/Users/kevinduranty/Library/Python/3.8/lib/python/site-packages/botbuilder/core/bot_framework_adapter.py\", line 493, in process_activity_with_identity\n",
      "    await self.run_pipeline(context, logic)\n",
      "  File \"/Users/kevinduranty/Library/Python/3.8/lib/python/site-packages/botbuilder/core/bot_adapter.py\", line 135, in run_pipeline\n",
      "    raise error\n",
      "  File \"/Users/kevinduranty/Library/Python/3.8/lib/python/site-packages/botbuilder/core/bot_adapter.py\", line 128, in run_pipeline\n",
      "    return await self._middleware.receive_activity_with_status(\n",
      "  File \"/Users/kevinduranty/Library/Python/3.8/lib/python/site-packages/botbuilder/core/middleware_set.py\", line 69, in receive_activity_with_status\n",
      "    return await self.receive_activity_internal(context, callback)\n",
      "  File \"/Users/kevinduranty/Library/Python/3.8/lib/python/site-packages/botbuilder/core/middleware_set.py\", line 79, in receive_activity_internal\n",
      "    return await callback(context)\n",
      "  File \"/var/folders/pd/d9xkkvws5r5f_x34lthx34ph0000gn/T/ipykernel_3730/1317316088.py\", line 31, in turn_call\n",
      "    await ebot.on_turn(turn_context)\n",
      "NameError: name 'ebot' is not defined\n",
      "Task exception was never retrieved\n",
      "future: <Task finished name='Task-8' coro=<BotFrameworkAdapter.process_activity() done, defined at /Users/kevinduranty/Library/Python/3.8/lib/python/site-packages/botbuilder/core/bot_framework_adapter.py:427> exception=NameError(\"name 'ebot' is not defined\")>\n",
      "Traceback (most recent call last):\n",
      "  File \"/Users/kevinduranty/Library/Python/3.8/lib/python/site-packages/botbuilder/core/bot_framework_adapter.py\", line 451, in process_activity\n",
      "    return await self.process_activity_with_identity(activity, identity, logic)\n",
      "  File \"/Users/kevinduranty/Library/Python/3.8/lib/python/site-packages/botbuilder/core/bot_framework_adapter.py\", line 493, in process_activity_with_identity\n",
      "    await self.run_pipeline(context, logic)\n",
      "  File \"/Users/kevinduranty/Library/Python/3.8/lib/python/site-packages/botbuilder/core/bot_adapter.py\", line 135, in run_pipeline\n",
      "    raise error\n",
      "  File \"/Users/kevinduranty/Library/Python/3.8/lib/python/site-packages/botbuilder/core/bot_adapter.py\", line 128, in run_pipeline\n",
      "    return await self._middleware.receive_activity_with_status(\n",
      "  File \"/Users/kevinduranty/Library/Python/3.8/lib/python/site-packages/botbuilder/core/middleware_set.py\", line 69, in receive_activity_with_status\n",
      "    return await self.receive_activity_internal(context, callback)\n",
      "  File \"/Users/kevinduranty/Library/Python/3.8/lib/python/site-packages/botbuilder/core/middleware_set.py\", line 79, in receive_activity_internal\n",
      "    return await callback(context)\n",
      "  File \"/var/folders/pd/d9xkkvws5r5f_x34lthx34ph0000gn/T/ipykernel_3730/1317316088.py\", line 31, in turn_call\n",
      "    await ebot.on_turn(turn_context)\n",
      "NameError: name 'ebot' is not defined\n"
     ]
    },
    {
     "name": "stderr",
     "output_type": "stream",
     "text": [
      "Task exception was never retrieved\n",
      "future: <Task finished name='Task-9' coro=<BotFrameworkAdapter.process_activity() done, defined at /Users/kevinduranty/Library/Python/3.8/lib/python/site-packages/botbuilder/core/bot_framework_adapter.py:427> exception=NameError(\"name 'ebot' is not defined\")>\n",
      "Traceback (most recent call last):\n",
      "  File \"/Users/kevinduranty/Library/Python/3.8/lib/python/site-packages/botbuilder/core/bot_framework_adapter.py\", line 451, in process_activity\n",
      "    return await self.process_activity_with_identity(activity, identity, logic)\n",
      "  File \"/Users/kevinduranty/Library/Python/3.8/lib/python/site-packages/botbuilder/core/bot_framework_adapter.py\", line 493, in process_activity_with_identity\n",
      "    await self.run_pipeline(context, logic)\n",
      "  File \"/Users/kevinduranty/Library/Python/3.8/lib/python/site-packages/botbuilder/core/bot_adapter.py\", line 135, in run_pipeline\n",
      "    raise error\n",
      "  File \"/Users/kevinduranty/Library/Python/3.8/lib/python/site-packages/botbuilder/core/bot_adapter.py\", line 128, in run_pipeline\n",
      "    return await self._middleware.receive_activity_with_status(\n",
      "  File \"/Users/kevinduranty/Library/Python/3.8/lib/python/site-packages/botbuilder/core/middleware_set.py\", line 69, in receive_activity_with_status\n",
      "    return await self.receive_activity_internal(context, callback)\n",
      "  File \"/Users/kevinduranty/Library/Python/3.8/lib/python/site-packages/botbuilder/core/middleware_set.py\", line 79, in receive_activity_internal\n",
      "    return await callback(context)\n",
      "  File \"/var/folders/pd/d9xkkvws5r5f_x34lthx34ph0000gn/T/ipykernel_3730/1317316088.py\", line 31, in turn_call\n",
      "    await ebot.on_turn(turn_context)\n",
      "NameError: name 'ebot' is not defined\n"
     ]
    }
   ],
   "source": [
    "import json\n",
    "from flask import Flask,request,Response\n",
    "from botbuilder.schema import Activity\n",
    "from botbuilder.core import BotFrameworkAdapter,BotFrameworkAdapterSettings\n",
    "import asyncio\n",
    "\n",
    "from echobot import EchoBot\n",
    "\n",
    "app = Flask(__name__)\n",
    "loop = asyncio.get_event_loop()\n",
    "\n",
    "botadaptersettings = BotFrameworkAdapterSettings(\"\",\"\")\n",
    "botadapter = BotFrameworkAdapter(botadaptersettings)\n",
    "\n",
    "\n",
    "# Create the bot\n",
    "BOT = EchoBot()\n",
    "\n",
    "\n",
    "@app.route(\"/api/messages\",methods=[\"POST\"])\n",
    "def messages():\n",
    "    if \"application/json\" in request.headers[\"content-type\"]:\n",
    "        jsonmessage = request.json\n",
    "    else:\n",
    "        return Response(status=415)\n",
    "\n",
    "    activity = Activity().deserialize(jsonmessage)\n",
    "\n",
    "\n",
    "    async def turn_call(turn_context):\n",
    "        await ebot.on_turn(turn_context)\n",
    "        \n",
    "    task = loop.create_task(botadapter.process_activity(activity,\"\",turn_call))\n",
    "    loop.run_until_complete(task)\n",
    "\n",
    "if __name__ == '__main__':\n",
    "    app.run('localhost',3978)"
   ]
  },
  {
   "cell_type": "code",
   "execution_count": null,
   "id": "a86379a7",
   "metadata": {},
   "outputs": [],
   "source": []
  }
 ],
 "metadata": {
  "kernelspec": {
   "display_name": "p10",
   "language": "python",
   "name": "p10"
  },
  "language_info": {
   "codemirror_mode": {
    "name": "ipython",
    "version": 3
   },
   "file_extension": ".py",
   "mimetype": "text/x-python",
   "name": "python",
   "nbconvert_exporter": "python",
   "pygments_lexer": "ipython3",
   "version": "3.8.2"
  }
 },
 "nbformat": 4,
 "nbformat_minor": 5
}
